<?xml version="1.0" encoding="utf-8"?>
<!-- This URDF was automatically created by SolidWorks to URDF Exporter! Originally created by Stephen Brawner (brawner@gmail.com) 
     Commit Version: 1.5.1-0-g916b5db  Build Version: 1.5.7152.31018
     For more information, please see http://wiki.ros.org/sw_urdf_exporter -->
<robot
  name="export4">
  <link
    name="base_link">
    <inertial>
      <origin
        xyz="0.0256565407097255 -0.0927962665591914 -0.107673119403125"
        rpy="0 0 0" />
      <mass
        value="3.42380866610349" />
      <inertia
        ixx="0.00804133201134247"
        ixy="-4.59293582870988E-06"
        ixz="0.00018780021138458"
        iyy="0.013557067485748"
        iyz="3.85040670673255E-06"
        izz="0.0125180978858311" />
    </inertial>
    <visual>
      <origin
        xyz="0 0 0"
        rpy="0 0 0" />
      <geometry>
        <mesh
          filename="package://export4/meshes/base_link.STL" />
      </geometry>
      <material
        name="">
        <color
          rgba="0.752941176470588 0.752941176470588 0.752941176470588 1" />
      </material>
    </visual>
    <collision>
      <origin
        xyz="0 0 0"
        rpy="0 0 0" />
      <geometry>
        <mesh
          filename="package://export4/meshes/base_link.STL" />
      </geometry>
    </collision>
  </link>
  <link
    name="ThumbL1">
    <inertial>
      <origin
        xyz="-0.00116215938584539 0.0573980209020999 0.0130345346076818"
        rpy="0 0 0" />
      <mass
        value="0.0160938232340567" />
      <inertia
        ixx="4.82391090636513E-06"
        ixy="2.84402504211663E-07"
        ixz="-1.49887567721572E-07"
        iyy="9.89860795091054E-07"
        iyz="4.00426578308744E-08"
        izz="4.17534491100527E-06" />
    </inertial>
    <visual>
      <origin
        xyz="0 0 0"
        rpy="0 0 0" />
      <geometry>
        <mesh
          filename="package://export4/meshes/ThumbL1.STL" />
      </geometry>
      <material
        name="">
        <color
          rgba="0.741176470588235 0.733333333333333 0.725490196078431 1" />
      </material>
    </visual>
    <collision>
      <origin
        xyz="0 0 0"
        rpy="0 0 0" />
      <geometry>
        <mesh
          filename="package://export4/meshes/ThumbL1.STL" />
      </geometry>
    </collision>
  </link>
  <joint
    name="Thumb_J1_palm"
    type="revolute">
    <origin
      xyz="0.0253704940670463 -0.107730311468469 -0.00564602169271088"
      rpy="1.36904942480943 0.835713305810846 -0.290192523798073" />
    <parent
      link="base_link" />
    <child
      link="ThumbL1" />
    <axis
      xyz="0.0696339767603201 -0.997572608525587 0" />
    <limit
      lower="0"
      upper="1.58"
      effort="0"
      velocity="1" />
  </joint>
  <link
    name="ThumbL2">
    <inertial>
      <origin
        xyz="0.00984172799621763 0.00950940348832564 0.0205719590920846"
        rpy="0 0 0" />
      <mass
        value="0.0104393141676268" />
      <inertia
        ixx="7.72201823158381E-07"
        ixy="-1.69484840963532E-08"
        ixz="-8.43759114315331E-08"
        iyy="7.77475612919456E-07"
        iyz="-2.25662194748926E-08"
        izz="5.00016280685962E-07" />
    </inertial>
    <visual>
      <origin
        xyz="0 0 0"
        rpy="0 0 0" />
      <geometry>
        <mesh
          filename="package://export4/meshes/ThumbL2.STL" />
      </geometry>
      <material
        name="">
        <color
          rgba="0.741176470588235 0.733333333333333 0.725490196078431 1" />
      </material>
    </visual>
    <collision>
      <origin
        xyz="0 0 0"
        rpy="0 0 0" />
      <geometry>
        <mesh
          filename="package://export4/meshes/ThumbL2.STL" />
      </geometry>
    </collision>
  </link>
  <joint
    name="Thumb_J2_AA"
    type="revolute">
    <origin
      xyz="0.0116011612623766 0.0714243203561624 0.0155920000826014"
      rpy="0.26621136450295 -0.382406486230405 2.06559118209411" />
    <parent
      link="ThumbL1" />
    <child
      link="ThumbL2" />
    <axis
      xyz="0.533983512123466 0.752625147265207 0.38524926539101" />
    <limit
      lower="0"
      upper="1.58"
      effort="0"
      velocity="1" />
  </joint>
  <link
    name="ThumbL3">
    <inertial>
      <origin
        xyz="0.0156326329367355 0.012646164023356 0.0574819040555708"
        rpy="0 0 0" />
      <mass
        value="0.00960221577736359" />
      <inertia
        ixx="1.24254398810311E-06"
        ixy="7.97168513479527E-08"
        ixz="-1.89970734891026E-07"
        iyy="1.16974540298146E-06"
        iyz="2.89060111800438E-07"
        izz="5.27848773025217E-07" />
    </inertial>
    <visual>
      <origin
        xyz="0 0 0"
        rpy="0 0 0" />
      <geometry>
        <mesh
          filename="package://export4/meshes/ThumbL3.STL" />
      </geometry>
      <material
        name="">
        <color
          rgba="0.741176470588235 0.733333333333333 0.725490196078431 1" />
      </material>
    </visual>
    <collision>
      <origin
        xyz="0 0 0"
        rpy="0 0 0" />
      <geometry>
        <mesh
          filename="package://export4/meshes/ThumbL3.STL" />
      </geometry>
    </collision>
  </link>
  <joint
    name="Thumb_J3_FE1"
    type="revolute">
    <origin
      xyz="0.0210282508749524 -0.0219666986100594 0.0128222251300471"
      rpy="-0.323401837524802 0.0594865698013315 0.499082256990666" />
    <parent
      link="ThumbL2" />
    <child
      link="ThumbL3" />
    <axis
      xyz="0.548878290339934 0.03800792096886 -0.835037735876131" />
    <limit
      lower="0"
      upper="1.58"
      effort="0"
      velocity="1" />
  </joint>
  <link
    name="ThumbL4_Tip">
    <inertial>
      <origin
        xyz="0.0180187808342411 0.0660544692245074 -0.0128069951900332"
        rpy="0 0 0" />
      <mass
        value="0.00888392010965421" />
      <inertia
        ixx="4.26652772160937E-07"
        ixy="2.64022497949969E-08"
        ixz="-4.16594760221795E-08"
        iyy="3.55264090745555E-07"
        iyz="6.44783527280813E-08"
        izz="5.04426700755442E-07" />
    </inertial>
    <visual>
      <origin
        xyz="0 0 0"
        rpy="0 0 0" />
      <geometry>
        <mesh
          filename="package://export4/meshes/ThumbL4_Tip.STL" />
      </geometry>
      <material
        name="">
        <color
          rgba="0.745098039215686 0.745098039215686 0.745098039215686 1" />
      </material>
    </visual>
    <collision>
      <origin
        xyz="0 0 0"
        rpy="0 0 0" />
      <geometry>
        <mesh
          filename="package://export4/meshes/ThumbL4_Tip.STL" />
      </geometry>
    </collision>
  </link>
  <joint
    name="Thumb_J3_FE2"
    type="revolute">
    <origin
      xyz="0.0340761679604119 -0.0128797397280206 0.0218123515851108"
      rpy="1.83346470963881 -0.0797212817443392 2.46760407767054" />
    <parent
      link="ThumbL3" />
    <child
      link="ThumbL4_Tip" />
    <axis
      xyz="0.470351806777558 0.676018510829762 -0.567246111380763" />
    <limit
      lower="0"
      upper="1.58"
      effort="0"
      velocity="1" />
  </joint>
  <link
    name="IndexL1">
    <inertial>
      <origin
        xyz="-0.0110036077611169 0.00200680379762937 -0.0297326430566325"
        rpy="0 0 0" />
      <mass
        value="0.00948156720538572" />
      <inertia
        ixx="1.23486015146193E-06"
        ixy="-2.08815385827307E-09"
        ixz="2.30676583172295E-08"
        iyy="1.25267470082058E-06"
        iyz="1.29542869448048E-08"
        izz="3.64578884958659E-07" />
    </inertial>
    <visual>
      <origin
        xyz="0 0 0"
        rpy="0 0 0" />
      <geometry>
        <mesh
          filename="package://export4/meshes/IndexL1.STL" />
      </geometry>
      <material
        name="">
        <color
          rgba="0.741176470588235 0.733333333333333 0.725490196078431 1" />
      </material>
    </visual>
    <collision>
      <origin
        xyz="0 0 0"
        rpy="0 0 0" />
      <geometry>
        <mesh
          filename="package://export4/meshes/IndexL1.STL" />
      </geometry>
    </collision>
  </link>
  <joint
    name="Index_J1_FE"
    type="revolute">
    <origin
      xyz="0.0728759784819037 -0.110053392519513 0.124865711151128"
      rpy="2.05610648406236 -0.197122708761004 3.14020353348554" />
    <parent
      link="base_link" />
    <child
      link="IndexL1" />
    <axis
      xyz="1 0 0" />
    <limit
      lower="0"
      upper="1.58"
      effort="0"
      velocity="1" />
  </joint>
  <link
    name="IndexL2">
    <inertial>
      <origin
        xyz="-0.0100449021281075 -0.048553130986567 -0.0528275886747485"
        rpy="0 0 0" />
      <mass
        value="0.00793319371044694" />
      <inertia
        ixx="7.71405447074959E-07"
        ixy="-9.74049350697167E-10"
        ixz="-1.91095922570681E-08"
        iyy="7.82665157872115E-07"
        iyz="-6.79621467122643E-08"
        izz="3.27795049653817E-07" />
    </inertial>
    <visual>
      <origin
        xyz="0 0 0"
        rpy="0 0 0" />
      <geometry>
        <mesh
          filename="package://export4/meshes/IndexL2.STL" />
      </geometry>
      <material
        name="">
        <color
          rgba="0.741176470588235 0.733333333333333 0.725490196078431 1" />
      </material>
    </visual>
    <collision>
      <origin
        xyz="0 0 0"
        rpy="0 0 0" />
      <geometry>
        <mesh
          filename="package://export4/meshes/IndexL2.STL" />
      </geometry>
    </collision>
  </link>
  <joint
    name="Index_J2_FE"
    type="revolute">
    <origin
      xyz="-0.00475302703995798 0.0416064416256316 -0.00501005631231227"
      rpy="0.190900346751885 0 0" />
    <parent
      link="IndexL1" />
    <child
      link="IndexL2" />
    <axis
      xyz="1 0 0" />
    <limit
      lower="0"
      upper="1.58"
      effort="0"
      velocity="1" />
  </joint>
  <link
    name="IndexL3">
    <inertial>
      <origin
        xyz="-0.0286304841590055 0.0866508909843542 0.0209018321125839"
        rpy="0 0 0" />
      <mass
        value="0.00673176599479462" />
      <inertia
        ixx="2.50188582390304E-07"
        ixy="-3.17896614497214E-08"
        ixz="1.88528917518108E-08"
        iyy="2.7060482534551E-07"
        iyz="-2.88755724101392E-08"
        izz="2.42898614883715E-07" />
    </inertial>
    <visual>
      <origin
        xyz="0 0 0"
        rpy="0 0 0" />
      <geometry>
        <mesh
          filename="package://export4/meshes/IndexL3.STL" />
      </geometry>
      <material
        name="">
        <color
          rgba="0.745098039215686 0.745098039215686 0.745098039215686 1" />
      </material>
    </visual>
    <collision>
      <origin
        xyz="0 0 0"
        rpy="0 0 0" />
      <geometry>
        <mesh
          filename="package://export4/meshes/IndexL3.STL" />
      </geometry>
    </collision>
  </link>
  <joint
    name="Index_J3_FE"
    type="revolute">
    <origin
      xyz="0 0.0205736699231283 -0.0252931793551903"
      rpy="-2.55340530146095 0.273914553484709 0.535024949097678" />
    <parent
      link="IndexL2" />
    <child
      link="IndexL3" />
    <axis
      xyz="0.828185035535657 0.295063903767517 -0.476494322745064" />
    <limit
      lower="0"
      upper="1.58"
      effort="0"
      velocity="1" />
  </joint>
  <link
    name="MiddleL1">
    <inertial>
      <origin
        xyz="-0.011880008315849 -0.00717882392396691 -0.0327506433702228"
        rpy="0 0 0" />
      <mass
        value="0.0106218099339646" />
      <inertia
        ixx="1.72397950128707E-06"
        ixy="4.9828873586339E-09"
        ixz="2.56429419919935E-08"
        iyy="1.65168377799189E-06"
        iyz="-3.30306477224266E-07"
        izz="4.85956963503466E-07" />
    </inertial>
    <visual>
      <origin
        xyz="0 0 0"
        rpy="0 0 0" />
      <geometry>
        <mesh
          filename="package://export4/meshes/MiddleL1.STL" />
      </geometry>
      <material
        name="">
        <color
          rgba="0.741176470588235 0.733333333333333 0.725490196078431 1" />
      </material>
    </visual>
    <collision>
      <origin
        xyz="0 0 0"
        rpy="0 0 0" />
      <geometry>
        <mesh
          filename="package://export4/meshes/MiddleL1.STL" />
      </geometry>
    </collision>
  </link>
  <joint
    name="Middle_J1_FE"
    type="revolute">
    <origin
      xyz="0.0437423488509242 -0.11000514327254 0.12644792794842"
      rpy="2.69942035733912 -0.0524037668900937 3.13989449923042" />
    <parent
      link="base_link" />
    <child
      link="MiddleL1" />
    <axis
      xyz="0.999999999250854 -3.34230441381843E-05 -1.95241509780389E-05" />
    <limit
      lower="0"
      upper="1.58"
      effort="0"
      velocity="1" />
  </joint>
  <link
    name="MiddleL2">
    <inertial>
      <origin
        xyz="-0.0124608744987204 -0.0515716339614584 -0.0162742831244383"
        rpy="0 0 0" />
      <mass
        value="0.00867664145866706" />
      <inertia
        ixx="9.64644124622515E-07"
        ixy="-1.09494940033272E-08"
        ixz="-1.80361956894846E-08"
        iyy="7.60328965721153E-07"
        iyz="-3.06082045643428E-07"
        izz="5.6373822416277E-07" />
    </inertial>
    <visual>
      <origin
        xyz="0 0 0"
        rpy="0 0 0" />
      <geometry>
        <mesh
          filename="package://export4/meshes/MiddleL2.STL" />
      </geometry>
      <material
        name="">
        <color
          rgba="0.741176470588235 0.733333333333333 0.725490196078431 1" />
      </material>
    </visual>
    <collision>
      <origin
        xyz="0 0 0"
        rpy="0 0 0" />
      <geometry>
        <mesh
          filename="package://export4/meshes/MiddleL2.STL" />
      </geometry>
    </collision>
  </link>
  <joint
    name="Middle_J2_FE"
    type="revolute">
    <origin
      xyz="-0.00299715546443679 0.0252338128043619 -0.0415509163921233"
      rpy="0.319244132162092 0 0" />
    <parent
      link="MiddleL1" />
    <child
      link="MiddleL2" />
    <axis
      xyz="0.999999999250854 -3.34230440799095E-05 -1.95241510214003E-05" />
    <limit
      lower="0"
      upper="1.58"
      effort="0"
      velocity="1" />
  </joint>
  <link
    name="MiddleL3">
    <inertial>
      <origin
        xyz="-0.027878184039032 0.0559938093699805 0.00854237944901273"
        rpy="0 0 0" />
      <mass
        value="0.00789820476468208" />
      <inertia
        ixx="3.50733185550165E-07"
        ixy="-1.08078512935028E-08"
        ixz="4.26832343626953E-08"
        iyy="2.9021245729533E-07"
        iyz="-3.86701485394314E-08"
        izz="3.72559133468608E-07" />
    </inertial>
    <visual>
      <origin
        xyz="0 0 0"
        rpy="0 0 0" />
      <geometry>
        <mesh
          filename="package://export4/meshes/MiddleL3.STL" />
      </geometry>
      <material
        name="">
        <color
          rgba="0.0901960784313725 0.141176470588235 0.968627450980392 1" />
      </material>
    </visual>
    <collision>
      <origin
        xyz="0 0 0"
        rpy="0 0 0" />
      <geometry>
        <mesh
          filename="package://export4/meshes/MiddleL3.STL" />
      </geometry>
    </collision>
  </link>
  <joint
    name="Middle_J3_FE"
    type="revolute">
    <origin
      xyz="0 -0.0175788371775351 -0.0325142111389774"
      rpy="-3.04592455914712 0.494134815575123 0.34606531066873" />
    <parent
      link="MiddleL2" />
    <child
      link="MiddleL3" />
    <axis
      xyz="0.828185035535662 0.295063903767477 -0.476494322745079" />
    <limit
      lower="0"
      upper="1.58"
      effort="0"
      velocity="1" />
  </joint>
  <link
    name="RingL1">
    <inertial>
      <origin
        xyz="-0.0163487558604147 0.0173098350134891 0.0233065244791423"
        rpy="0 0 0" />
      <mass
        value="0.00928158479591969" />
      <inertia
        ixx="1.16576204700683E-06"
        ixy="-1.31558149258871E-08"
        ixz="-1.85540220657492E-08"
        iyy="8.45795249712863E-07"
        iyz="-4.04705425724502E-07"
        izz="6.96549873796174E-07" />
    </inertial>
    <visual>
      <origin
        xyz="0 0 0"
        rpy="0 0 0" />
      <geometry>
        <mesh
          filename="package://export4/meshes/RingL1.STL" />
      </geometry>
      <material
        name="">
        <color
          rgba="0.741176470588235 0.733333333333333 0.725490196078431 1" />
      </material>
    </visual>
    <collision>
      <origin
        xyz="0 0 0"
        rpy="0 0 0" />
      <geometry>
        <mesh
          filename="package://export4/meshes/RingL1.STL" />
      </geometry>
    </collision>
  </link>
  <joint
    name="Ring_J1_FE"
    type="revolute">
    <origin
      xyz="0.0108510073339124 -0.109941670021049 0.123332723693398"
      rpy="0.540544369703017 0.0928916951867764 3.13966571992626" />
    <parent
      link="base_link" />
    <child
      link="RingL1" />
    <axis
      xyz="1 0 0" />
    <limit
      lower="0"
      upper="1.58"
      effort="0"
      velocity="1" />
  </joint>
  <link
    name="RingL2">
    <inertial>
      <origin
        xyz="-0.015752243985331 0.00610562223237718 0.0263537187262462"
        rpy="0 0 0" />
      <mass
        value="0.00847709423518467" />
      <inertia
        ixx="9.19840294015484E-07"
        ixy="7.69411840107655E-09"
        ixz="1.91878763557384E-08"
        iyy="8.16550180826541E-07"
        iyz="-2.42956922308735E-07"
        izz="4.58295533608766E-07" />
    </inertial>
    <visual>
      <origin
        xyz="0 0 0"
        rpy="0 0 0" />
      <geometry>
        <mesh
          filename="package://export4/meshes/RingL2.STL" />
      </geometry>
      <material
        name="">
        <color
          rgba="0.741176470588235 0.733333333333333 0.725490196078431 1" />
      </material>
    </visual>
    <collision>
      <origin
        xyz="0 0 0"
        rpy="0 0 0" />
      <geometry>
        <mesh
          filename="package://export4/meshes/RingL2.STL" />
      </geometry>
    </collision>
  </link>
  <joint
    name="Ring_J2_FE"
    type="revolute">
    <origin
      xyz="-0.00423101282970504 0.0291613635308715 0.0283346162320914"
      rpy="-0.287448254981958 0 0" />
    <parent
      link="RingL1" />
    <child
      link="RingL2" />
    <axis
      xyz="1 0 0" />
    <limit
      lower="0"
      upper="1.58"
      effort="0"
      velocity="1" />
  </joint>
  <link
    name="RingL3">
    <inertial>
      <origin
        xyz="-0.012865912578455 0.0244952231285156 0.00919042640313261"
        rpy="0 0 0" />
      <mass
        value="0.00744651698122299" />
      <inertia
        ixx="2.74918577521189E-07"
        ixy="1.41670121944966E-12"
        ixz="2.10034897282317E-12"
        iyy="2.63444656852281E-07"
        iyz="3.2948560824132E-08"
        izz="3.52496021883032E-07" />
    </inertial>
    <visual>
      <origin
        xyz="0 0 0"
        rpy="0 0 0" />
      <geometry>
        <mesh
          filename="package://export4/meshes/RingL3.STL" />
      </geometry>
      <material
        name="">
        <color
          rgba="0.745098039215686 0.745098039215686 0.745098039215686 1" />
      </material>
    </visual>
    <collision>
      <origin
        xyz="0 0 0"
        rpy="0 0 0" />
      <geometry>
        <mesh
          filename="package://export4/meshes/RingL3.STL" />
      </geometry>
    </collision>
  </link>
  <joint
    name="Ring_J3_FE"
    type="revolute">
    <origin
      xyz="-0.00106109890529309 0.0261399019066498 0.0248110283606132"
      rpy="1.24183684479456 0 0" />
    <parent
      link="RingL2" />
    <child
      link="RingL3" />
    <axis
      xyz="1 0 0" />
    <limit
      lower="0"
      upper="1.58"
      effort="0"
      velocity="1" />
  </joint>
  <link
    name="LittleL1">
    <inertial>
      <origin
        xyz="-0.0215940474328127 0.000692901419905162 0.0299883552750344"
        rpy="0 0 0" />
      <mass
        value="0.00806590362868623" />
      <inertia
        ixx="7.78393714417357E-07"
        ixy="1.21916784774548E-08"
        ixz="-1.14807141721596E-07"
        iyy="8.23520634329069E-07"
        iyz="2.97998922451299E-08"
        izz="3.52495174325864E-07" />
    </inertial>
    <visual>
      <origin
        xyz="0 0 0"
        rpy="0 0 0" />
      <geometry>
        <mesh
          filename="package://export4/meshes/LittleL1.STL" />
      </geometry>
      <material
        name="">
        <color
          rgba="0.752941176470588 0.752941176470588 0.752941176470588 1" />
      </material>
    </visual>
    <collision>
      <origin
        xyz="0 0 0"
        rpy="0 0 0" />
      <geometry>
        <mesh
          filename="package://export4/meshes/LittleL1.STL" />
      </geometry>
    </collision>
  </link>
  <joint
    name="Little_J1_FE"
    type="revolute">
    <origin
      xyz="-0.0279454614674053 -0.109854803994473 0.113124982944162"
      rpy="-0.683067167299937 0.171216603389238 -2.88833288836769" />
    <parent
      link="base_link" />
    <child
      link="LittleL1" />
    <axis
      xyz="0.9665623406842 -0.143502933987546 -0.212518586264937" />
    <limit
      lower="0"
      upper="1.58"
      effort="0"
      velocity="1" />
  </joint>
  <link
    name="LittleL2">
    <inertial>
      <origin
        xyz="-0.0215377749282379 0.00323097308133327 0.0310194016380853"
        rpy="0 0 0" />
      <mass
        value="0.00742143387924883" />
      <inertia
        ixx="6.64527574276134E-07"
        ixy="1.75264892639144E-08"
        ixz="-4.09481962845885E-08"
        iyy="6.62216430884232E-07"
        iyz="9.69499223671467E-08"
        izz="3.33816158144186E-07" />
    </inertial>
    <visual>
      <origin
        xyz="0 0 0"
        rpy="0 0 0" />
      <geometry>
        <mesh
          filename="package://export4/meshes/LittleL2.STL" />
      </geometry>
      <material
        name="">
        <color
          rgba="0.752941176470588 0.752941176470588 0.752941176470588 1" />
      </material>
    </visual>
    <collision>
      <origin
        xyz="0 0 0"
        rpy="0 0 0" />
      <geometry>
        <mesh
          filename="package://export4/meshes/LittleL2.STL" />
      </geometry>
    </collision>
  </link>
  <joint
    name="Little_J2_FE"
    type="revolute">
    <origin
      xyz="0.00195863243073287 -0.0103854986303937 0.0319234697402389"
      rpy="-0.34334095190958 0.0631672147791817 0.0657186339990364" />
    <parent
      link="LittleL1" />
    <child
      link="LittleL2" />
    <axis
      xyz="0.96656234068422 -0.143502933987541 -0.212518586264844" />
    <limit
      lower="0"
      upper="1.58"
      effort="0"
      velocity="1" />
  </joint>
  <link
    name="LittleL3">
    <inertial>
      <origin
        xyz="-0.0321664082930794 0.0143141210297598 0.0124783996854492"
        rpy="0 0 0" />
      <mass
        value="0.00616235200309414" />
      <inertia
        ixx="2.10898618785592E-07"
        ixy="-1.02765898980234E-08"
        ixz="3.29277404521148E-08"
        iyy="2.00063482775281E-07"
        iyz="-1.05689280380039E-08"
        izz="2.38973377312664E-07" />
    </inertial>
    <visual>
      <origin
        xyz="0 0 0"
        rpy="0 0 0" />
      <geometry>
        <mesh
          filename="package://export4/meshes/LittleL3.STL" />
      </geometry>
      <material
        name="">
        <color
          rgba="0.752941176470588 0.752941176470588 0.752941176470588 1" />
      </material>
    </visual>
    <collision>
      <origin
        xyz="0 0 0"
        rpy="0 0 0" />
      <geometry>
        <mesh
          filename="package://export4/meshes/LittleL3.STL" />
      </geometry>
    </collision>
  </link>
  <joint
    name="Little_J3_FE"
    type="revolute">
    <origin
      xyz="0.00701734155191605 -0.0100198126120445 0.0272319953261571"
      rpy="1.2273581075963 0.397683579310761 -0.742784944270805" />
    <parent
      link="LittleL2" />
    <child
      link="LittleL3" />
    <axis
      xyz="0.828185035535954 0.295063903767513 -0.476494322744549" />
    <limit
      lower="0"
      upper="1.58"
      effort="0"
      velocity="1" />
  </joint>
</robot>